{"name": "test_add", "status": "failed", "statusDetails": {"message": "AssertionError: 计算有误\nassert 5 == 6", "trace": "self = <Case.test_mine.TestMine object at 0x109437850>\n\n    @allure.description(\"比较两值是否相等\")\n    def test_add(self):\n        a = 2\n        b = 3\n        c = a+b\n        d = a*b\n>       assert c==d,\"计算有误\"\nE       AssertionError: 计算有误\nE       assert 5 == 6\n\nCase/test_mine.py:22: AssertionError"}, "description": "比较两值是否相等", "start": 1587555109653, "stop": 1587555109653, "uuid": "930fb78f-ce39-4747-ab3a-65f2bf000c48", "historyId": "142849c1536d0e1edecd900add214d4d", "testCaseId": "09ff17ced9664e6d67c60f004995235b", "fullName": "Case.test_mine.TestMine#test_add", "labels": [{"name": "parentSuite", "value": "Case"}, {"name": "suite", "value": "test_mine"}, {"name": "subSuite", "value": "TestMine"}, {"name": "host", "value": "Parsons-Mac-mini.local"}, {"name": "thread", "value": "21476-MainThread"}, {"name": "framework", "value": "pytest"}, {"name": "language", "value": "cpython3"}, {"name": "package", "value": "Case.test_mine"}]}